<?xml version="1.0" ?>
<!-- =================================================================================== -->
<!-- |    This document was autogenerated by xacro from jaco_description/robots/standalone_arm.urdf.xacro | -->
<!-- |    EDITING THIS FILE BY HAND IS NOT RECOMMENDED                                 | -->
<!-- =================================================================================== -->
<robot name="jaco" xmlns:body="http://playerstage.sourceforge.net/gazebo/xmlschema/#body" xmlns:controller="http://playerstage.sourceforge.net/gazebo/xmlschema/#controller" xmlns:gazebo="http://playerstage.sourceforge.net/gazebo/xmlschema/#gz" xmlns:geom="http://playerstage.sourceforge.net/gazebo/xmlschema/#geom" xmlns:interface="http://playerstage.sourceforge.net/gazebo/xmlschema/#interface" xmlns:joint="http://playerstage.sourceforge.net/gazebo/xmlschema/#joint" xmlns:model="http://playerstage.sourceforge.net/gazebo/xmlschema/#model" xmlns:physics="http://playerstage.sourceforge.net/gazebo/xmlschema/#physics" xmlns:renderable="http://playerstage.sourceforge.net/gazebo/xmlschema/#renderable" xmlns:rendering="http://playerstage.sourceforge.net/gazebo/xmlschema/#rendering" xmlns:sensor="http://playerstage.sourceforge.net/gazebo/xmlschema/#sensor" xmlns:xacro="http://ros.org/wiki/xacro" xmlns:xi="http://www.w3.org/2001/XInclude">
  <joint name="jointarmtochair" type="fixed">
    <parent link="root"/>
    <child link="base_link"/>
    <origin rpy="0 0 0" xyz="0 0.4 0.5"/>
  </joint>
  <link name="base_link">
    <visual>
      <geometry>
        <box size="0.53 0.52 0.1"/>
      </geometry>
      <origin rpy="0 0 0" xyz="0.0 0 0.1"/>
      <material name="leather">
        <color rgba="0.5 0.5 0.5 1"/>
        <!--texture filename="package://jaco_description/urdf/leather.jpg" /-->
      </material>
    </visual>
    <collision>
      <geometry>
        <box size="0.53 0.52 0.1"/>
      </geometry>
      <origin rpy="0 0 0" xyz="0.0 0 0.1"/>
    </collision>
    <inertial>
      <mass value="150"/>
      <inertia ixx="0.4" ixy="0.0" ixz="0.0" iyy="0.4" iyz="0.0" izz="0.2"/>
    </inertial>
  </link>
  <link name="back">
    <visual>
      <geometry>
        <box size="0.1 0.43 0.52"/>
      </geometry>
      <!--origin rpy="0 0 0" xyz="-0.5 0 0.3"/-->
      <material name="leather"/>
    </visual>
  </link>
  <joint name="base_link_to_back" type="fixed">
    <parent link="base_link"/>
    <child link="back"/>
    <origin xyz="-0.28 0 0.375"/>
  </joint>
  <link name="back_head">
    <visual>
      <geometry>
        <box size="0.1 0.23 0.18"/>
      </geometry>
      <!--origin rpy="0 0 0" xyz="-0.5 0 0.3"/-->
      <material name="leather"/>
    </visual>
  </link>
  <joint name="base_link_to_back_head" type="fixed">
    <parent link="base_link"/>
    <child link="back_head"/>
    <origin xyz="-0.28 0 0.7"/>
  </joint>
  <link name="arm_rest_right">
    <visual>
      <geometry>
        <box size="0.41 0.07 0.05"/>
      </geometry>
      <!--origin rpy="0 0 0" xyz="-0.5 0 0.3"/-->
      <material name="leather"/>
    </visual>
  </link>
  <joint name="base_link_to_arm_rest_right" type="fixed">
    <parent link="base_link"/>
    <child link="arm_rest_right"/>
    <origin xyz="-0.06 0.24 0.25"/>
  </joint>
  <link name="arm_rest_left">
    <visual>
      <geometry>
        <box size="0.41 0.07 0.05"/>
      </geometry>
      <!--origin rpy="0 0 0" xyz="-0.5 0 0.3"/-->
      <material name="leather"/>
    </visual>
  </link>
  <joint name="base_link_to_arm_rest_left" type="fixed">
    <parent link="base_link"/>
    <child link="arm_rest_left"/>
    <origin xyz="-0.06 -0.24 0.25"/>
  </joint>
  <link name="left_wheel">
    <visual>
      <geometry>
        <cylinder length="0.09" radius="0.125"/>
      </geometry>
      <origin rpy="1.57075 0 0" xyz="0.0 0.0 0.0"/>
      <material name="wheel">
        <color rgba="0.0 0.0 0.9 1"/>
      </material>
    </visual>
    <collision>
      <geometry>
        <cylinder length="0.06" radius="0.12"/>
      </geometry>
      <origin rpy="1.57075 0 0" xyz="0.0 0.0 0.0"/>
    </collision>
  </link>
  <joint name="base_link_to_left_wheel" type="continuous">
    <parent link="base_link"/>
    <child link="left_wheel"/>
    <origin xyz="0.05 0.3 -0.3"/>
    <axis xyz="0 1 0"/>
  </joint>
  <link name="right_wheel">
    <visual>
      <geometry>
        <cylinder length="0.09" radius="0.125"/>
      </geometry>
      <origin rpy="1.57075 0 0" xyz="0.0 0.0 0.0"/>
      <material name="wheel"/>
    </visual>
    <collision>
      <geometry>
        <cylinder length="0.06" radius="0.12"/>
      </geometry>
      <origin rpy="1.57075 0 0" xyz="0.0 0.0 0.0"/>
    </collision>
  </link>
  <joint name="base_link_to_right_wheel" type="continuous">
    <parent link="base_link"/>
    <child link="right_wheel"/>
    <origin xyz="0.05 -0.3 -0.3"/>
    <axis xyz="0 1 0"/>
  </joint>
  <link name="motor_cage">
    <visual>
      <geometry>
        <box size="0.48 0.34 0.25"/>
      </geometry>
      <!--origin rpy="0 0 0" xyz="-0.5 0 0.3"/-->
      <material name="leather"/>
    </visual>
  </link>
  <joint name="base_link_to_motor_cage" type="fixed">
    <parent link="base_link"/>
    <child link="motor_cage"/>
    <origin xyz="0 0 -0.2"/>
  </joint>
  <link name="under_seat">
    <visual>
      <geometry>
        <box size="0.38 0.32 0.04"/>
      </geometry>
      <!--origin rpy="0 0 0" xyz="-0.5 0 0.3"/-->
      <material name="leather"/>
    </visual>
  </link>
  <joint name="base_link_to_under_seat" type="fixed">
    <parent link="base_link"/>
    <child link="under_seat"/>
    <origin xyz="0 0 0"/>
  </joint>
  <link name="foot_plate">
    <visual>
      <geometry>
        <box size="0.44 0.38 0.05"/>
      </geometry>
      <!--origin rpy="0 0 0" xyz="-0.5 0 0.3"/-->
      <material name="leather"/>
    </visual>
  </link>
  <joint name="base_link_to_foot_plate" type="fixed">
    <parent link="base_link"/>
    <child link="foot_plate"/>
    <origin xyz="0.47 0 -0.3"/>
  </joint>
  <link name="root">
    <visual>
      <origin rpy="0 0 0" xyz="0 0 0.5"/>
      <geometry>
        <box size="0 0 0"/>
      </geometry>
    </visual>
    <collision>
      <origin rpy="0 0 0" xyz="0 0 0.5"/>
      <geometry>
        <box size="0 0 0"/>
      </geometry>
    </collision>
  </link>
  <link name="jaco_link_base">
    <visual>
      <geometry>
        <mesh filename="package://jaco_description/meshes/jaco_link_base.min.dae" scale="0.0254 0.0254 0.0254"/>
      </geometry>
      <material name="carbon_fiber">
        <color rgba="0.792156862745098 0.819607843137255 0.933333333333333 1"/>
      </material>
    </visual>
    <collision>
      <geometry>
        <mesh filename="package://jaco_description/meshes/jaco_link_base.stl" scale="0.0254 0.0254 0.0254"/>
      </geometry>
    </collision>
  </link>
  <joint name="jaco_joint_base" type="fixed">
    <parent link="root"/>
    <child link="jaco_link_base"/>
    <axis xyz="0 0 0"/>
    <origin rpy="0 0 0" xyz="0 0 0.5"/>
    <limit effort="30" lower="-6.28318530718" upper="6.28318530718" velocity="5"/>
  </joint>
  <link name="jaco_link_1">
    <visual>
      <geometry>
        <mesh filename="package://jaco_description/meshes/jaco_link_1.min.dae" scale="0.0254 0.0254 0.0254"/>
      </geometry>
      <material name="carbon_fiber">
        <color rgba="0.792156862745098 0.819607843137255 0.933333333333333 1"/>
      </material>
    </visual>
    <collision>
      <geometry>
        <mesh filename="package://jaco_description/meshes/jaco_link_1.stl" scale="0.0254 0.0254 0.0254"/>
      </geometry>
    </collision>
  </link>
  <joint name="jaco_joint_1" type="revolute">
    <parent link="jaco_link_base"/>
    <child link="jaco_link_1"/>
    <axis xyz="0 0 1"/>
    <origin rpy="3.14159265359 0 0" xyz="0 0 0.1535"/>
    <limit effort="30" lower="-6.28318530718" upper="6.28318530718" velocity="5"/>
  </joint>
  <link name="jaco_link_2">
    <visual>
      <geometry>
        <mesh filename="package://jaco_description/meshes/jaco_link_2.min.dae" scale="0.0254 0.0254 0.0254"/>
      </geometry>
      <material name="carbon_fiber">
        <color rgba="0.792156862745098 0.819607843137255 0.933333333333333 1"/>
      </material>
    </visual>
    <collision>
      <geometry>
        <mesh filename="package://jaco_description/meshes/jaco_link_2.stl" scale="0.0254 0.0254 0.0254"/>
      </geometry>
    </collision>
  </link>
  <joint name="jaco_joint_2" type="revolute">
    <parent link="jaco_link_1"/>
    <child link="jaco_link_2"/>
    <axis xyz="0 0 1"/>
    <origin rpy="-1.57079632679 -1.57079632679 0" xyz="0 0 -0.1185"/>
    <limit effort="30" lower="0" upper="6.28318530718" velocity="5"/>
  </joint>
  <link name="jaco_link_3">
    <visual>
      <geometry>
        <mesh filename="package://jaco_description/meshes/jaco_link_3.min.dae" scale="0.0254 0.0254 0.0254"/>
      </geometry>
      <material name="carbon_fiber">
        <color rgba="0.792156862745098 0.819607843137255 0.933333333333333 1"/>
      </material>
    </visual>
    <collision>
      <geometry>
        <mesh filename="package://jaco_description/meshes/jaco_link_3.stl" scale="0.0254 0.0254 0.0254"/>
      </geometry>
    </collision>
  </link>
  <joint name="jaco_joint_3" type="revolute">
    <parent link="jaco_link_2"/>
    <child link="jaco_link_3"/>
    <axis xyz="0 0 1"/>
    <origin rpy="3.14159265359 0 3.14159265359" xyz="0.41 0 0"/>
    <limit effort="30" lower="0" upper="6.28318530718" velocity="5"/>
  </joint>
  <link name="jaco_link_4">
    <visual>
      <geometry>
        <mesh filename="package://jaco_description/meshes/jaco_link_4_5.min.dae" scale="0.0254 0.0254 0.0254"/>
      </geometry>
      <material name="carbon_fiber">
        <color rgba="0.792156862745098 0.819607843137255 0.933333333333333 1"/>
      </material>
    </visual>
    <collision>
      <geometry>
        <mesh filename="package://jaco_description/meshes/jaco_link_4_5.stl" scale="0.0254 0.0254 0.0254"/>
      </geometry>
    </collision>
  </link>
  <joint name="jaco_joint_4" type="revolute">
    <parent link="jaco_link_3"/>
    <child link="jaco_link_4"/>
    <axis xyz="0 0 1"/>
    <origin rpy="0 -1.57079632679 0" xyz="0.207 0 -0.01125"/>
    <limit effort="30" lower="-6.28318530718" upper="6.28318530718" velocity="5"/>
  </joint>
  <link name="jaco_link_5">
    <visual>
      <geometry>
        <mesh filename="package://jaco_description/meshes/jaco_link_4_5.min.dae" scale="0.0254 0.0254 0.0254"/>
      </geometry>
      <material name="carbon_fiber">
        <color rgba="0.792156862745098 0.819607843137255 0.933333333333333 1"/>
      </material>
    </visual>
    <collision>
      <geometry>
        <mesh filename="package://jaco_description/meshes/jaco_link_4_5.stl" scale="0.0254 0.0254 0.0254"/>
      </geometry>
    </collision>
  </link>
  <joint name="jaco_joint_5" type="revolute">
    <parent link="jaco_link_4"/>
    <child link="jaco_link_5"/>
    <axis xyz="0 0 1"/>
    <origin rpy="0 0.959931088597 3.14159265359" xyz="0.0343 0 -0.06588"/>
    <limit effort="30" lower="-6.28318530718" upper="6.28318530718" velocity="5"/>
  </joint>
  <link name="jaco_link_hand">
    <visual>
      <geometry>
        <mesh filename="package://jaco_description/meshes/jaco_link_hand.min.dae" scale="0.0254 0.0254 0.0254"/>
      </geometry>
      <material name="carbon_fiber">
        <color rgba="0.792156862745098 0.819607843137255 0.933333333333333 1"/>
      </material>
    </visual>
    <collision>
      <geometry>
        <mesh filename="package://jaco_description/meshes/jaco_link_hand.stl" scale="0.0254 0.0254 0.0254"/>
      </geometry>
    </collision>
  </link>
  <joint name="jaco_joint_6" type="revolute">
    <parent link="jaco_link_5"/>
    <child link="jaco_link_hand"/>
    <axis xyz="0 0 1"/>
    <origin rpy="0 0.959931088597 3.14159265359" xyz="0.0343 0 -0.06588"/>
    <limit effort="30" lower="-6.28318530718" upper="6.28318530718" velocity="5"/>
  </joint>
  <link name="jaco_large_ring_cover_1">
    <visual>
      <geometry>
        <mesh filename="package://jaco_description/meshes/jaco_large_ring_cover.min.dae" scale="0.0254 0.0254 0.0254"/>
      </geometry>
      <material name="carbon_fiber">
        <color rgba="0.792156862745098 0.819607843137255 0.933333333333333 1"/>
      </material>
    </visual>
    <collision>
      <geometry>
        <mesh filename="package://jaco_description/meshes/jaco_large_ring_cover.stl" scale="0.0254 0.0254 0.0254"/>
      </geometry>
    </collision>
  </link>
  <joint name="jaco_large_ring_cover_1_joint" type="fixed">
    <parent link="jaco_link_base"/>
    <child link="jaco_large_ring_cover_1"/>
    <axis xyz="0 0 1"/>
    <origin rpy="3.14159265359 0 0" xyz="0 0 0.1535"/>
    <limit effort="30" lower="-6.28318530718" upper="6.28318530718" velocity="5"/>
  </joint>
  <link name="jaco_large_ring_cover_2">
    <visual>
      <geometry>
        <mesh filename="package://jaco_description/meshes/jaco_large_ring_cover.min.dae" scale="0.0254 0.0254 0.0254"/>
      </geometry>
      <material name="carbon_fiber">
        <color rgba="0.792156862745098 0.819607843137255 0.933333333333333 1"/>
      </material>
    </visual>
    <collision>
      <geometry>
        <mesh filename="package://jaco_description/meshes/jaco_large_ring_cover.stl" scale="0.0254 0.0254 0.0254"/>
      </geometry>
    </collision>
  </link>
  <joint name="jaco_large_ring_cover_2_joint" type="fixed">
    <parent link="jaco_link_1"/>
    <child link="jaco_large_ring_cover_2"/>
    <axis xyz="0 0 1"/>
    <origin rpy="-1.57079632679 -1.57079632679 0" xyz="0 0 -0.1185"/>
    <limit effort="30" lower="0" upper="6.28318530718" velocity="5"/>
  </joint>
  <link name="jaco_large_ring_cover_3">
    <visual>
      <geometry>
        <mesh filename="package://jaco_description/meshes/jaco_large_ring_cover.min.dae" scale="0.0254 0.0254 0.0254"/>
      </geometry>
      <material name="carbon_fiber">
        <color rgba="0.792156862745098 0.819607843137255 0.933333333333333 1"/>
      </material>
    </visual>
    <collision>
      <geometry>
        <mesh filename="package://jaco_description/meshes/jaco_large_ring_cover.stl" scale="0.0254 0.0254 0.0254"/>
      </geometry>
    </collision>
  </link>
  <joint name="jaco_large_ring_cover_3_joint" type="fixed">
    <parent link="jaco_link_2"/>
    <child link="jaco_large_ring_cover_3"/>
    <axis xyz="0 0 1"/>
    <origin rpy="3.14159265359 0 3.14159265359" xyz="0.41 0 0"/>
    <limit effort="30" lower="0" upper="6.28318530718" velocity="5"/>
  </joint>
  <link name="jaco_small_ring_cover_1">
    <visual>
      <geometry>
        <mesh filename="package://jaco_description/meshes/jaco_small_ring_cover.min.dae" scale="0.0254 0.0254 0.0254"/>
      </geometry>
      <material name="carbon_fiber">
        <color rgba="0.792156862745098 0.819607843137255 0.933333333333333 1"/>
      </material>
    </visual>
    <collision>
      <geometry>
        <mesh filename="package://jaco_description/meshes/jaco_small_ring_cover.stl" scale="0.0254 0.0254 0.0254"/>
      </geometry>
    </collision>
  </link>
  <joint name="jaco_large_ring_cover_4_joint" type="fixed">
    <parent link="jaco_link_3"/>
    <child link="jaco_small_ring_cover_1"/>
    <axis xyz="0 0 1"/>
    <origin rpy="0 -1.57079632679 0" xyz="0.207 0 -0.01125"/>
    <limit effort="30" lower="-6.28318530718" upper="6.28318530718" velocity="5"/>
  </joint>
  <link name="jaco_small_ring_cover_2">
    <visual>
      <geometry>
        <mesh filename="package://jaco_description/meshes/jaco_small_ring_cover.min.dae" scale="0.0254 0.0254 0.0254"/>
      </geometry>
      <material name="carbon_fiber">
        <color rgba="0.792156862745098 0.819607843137255 0.933333333333333 1"/>
      </material>
    </visual>
    <collision>
      <geometry>
        <mesh filename="package://jaco_description/meshes/jaco_small_ring_cover.stl" scale="0.0254 0.0254 0.0254"/>
      </geometry>
    </collision>
  </link>
  <joint name="jaco_large_ring_cover_5_joint" type="fixed">
    <parent link="jaco_link_4"/>
    <child link="jaco_small_ring_cover_2"/>
    <axis xyz="0 0 1"/>
    <origin rpy="0 0.959931088597 3.14159265359" xyz="0.0343 0 -0.06588"/>
    <limit effort="30" lower="-6.28318530718" upper="6.28318530718" velocity="5"/>
  </joint>
  <link name="jaco_small_ring_cover_3">
    <visual>
      <geometry>
        <mesh filename="package://jaco_description/meshes/jaco_small_ring_cover.min.dae" scale="0.0254 0.0254 0.0254"/>
      </geometry>
      <material name="carbon_fiber">
        <color rgba="0.792156862745098 0.819607843137255 0.933333333333333 1"/>
      </material>
    </visual>
    <collision>
      <geometry>
        <mesh filename="package://jaco_description/meshes/jaco_small_ring_cover.stl" scale="0.0254 0.0254 0.0254"/>
      </geometry>
    </collision>
  </link>
  <joint name="jaco_large_ring_cover_6_joint" type="fixed">
    <parent link="jaco_link_5"/>
    <child link="jaco_small_ring_cover_3"/>
    <axis xyz="0 0 1"/>
    <origin rpy="0 0.959931088597 3.14159265359" xyz="0.0343 0 -0.06588"/>
    <limit effort="30" lower="-6.28318530718" upper="6.28318530718" velocity="5"/>
  </joint>
  <link name="jaco_link_finger_1">
    <visual>
      <geometry>
        <mesh filename="package://jaco_description/meshes/jaco_link_finger.min.dae" scale="0.0254 0.0254 0.0254"/>
      </geometry>
      <material name="carbon_fiber">
        <color rgba="0.792156862745098 0.819607843137255 0.933333333333333 1"/>
      </material>
    </visual>
    <collision>
      <geometry>
        <mesh filename="package://jaco_description/meshes/jaco_link_finger.stl" scale="0.0254 0.0254 0.0254"/>
      </geometry>
    </collision>
  </link>
  <joint name="jaco_joint_finger_1" type="revolute">
    <parent link="jaco_link_hand"/>
    <child link="jaco_link_finger_1"/>
    <axis xyz="0 0 1"/>
    <origin rpy="-1.7983 1.117 3.1416" xyz="-0.032578 0.0033 -0.12131"/>
    <limit effort="30" lower="0" upper="0.698131700798" velocity="5"/>
  </joint>
  <link name="jaco_link_finger_2">
    <visual>
      <geometry>
        <mesh filename="package://jaco_description/meshes/jaco_link_finger.min.dae" scale="0.0254 0.0254 0.0254"/>
      </geometry>
      <material name="carbon_fiber">
        <color rgba="0.792156862745098 0.819607843137255 0.933333333333333 1"/>
      </material>
    </visual>
    <collision>
      <geometry>
        <mesh filename="package://jaco_description/meshes/jaco_link_finger.stl" scale="0.0254 0.0254 0.0254"/>
      </geometry>
    </collision>
  </link>
  <joint name="jaco_joint_finger_2" type="revolute">
    <parent link="jaco_link_hand"/>
    <child link="jaco_link_finger_2"/>
    <axis xyz="0 0 1"/>
    <origin rpy="-1.5161 1.1459 0.23978" xyz="0.027788 0.0206 -0.12131"/>
    <limit effort="30" lower="0" upper="0.698131700798" velocity="5"/>
  </joint>
  <link name="jaco_link_finger_3">
    <visual>
      <geometry>
        <mesh filename="package://jaco_description/meshes/jaco_link_finger.min.dae" scale="0.0254 0.0254 0.0254"/>
      </geometry>
      <material name="carbon_fiber">
        <color rgba="0.792156862745098 0.819607843137255 0.933333333333333 1"/>
      </material>
    </visual>
    <collision>
      <geometry>
        <mesh filename="package://jaco_description/meshes/jaco_link_finger.stl" scale="0.0254 0.0254 0.0254"/>
      </geometry>
    </collision>
  </link>
  <joint name="jaco_joint_finger_3" type="revolute">
    <parent link="jaco_link_hand"/>
    <child link="jaco_link_finger_3"/>
    <axis xyz="0 0 1"/>
    <origin rpy="-1.6222 1.117 -0.23615" xyz="0.027788 -0.0206 -0.12131"/>
    <limit effort="30" lower="0" upper="0.698131700798" velocity="5"/>
  </joint>
  <link name="jaco_link_finger_tip_1">
    <visual>
      <geometry>
        <mesh filename="package://jaco_description/meshes/jaco_link_finger_tip.min.dae" scale="0.0254 0.0254 0.0254"/>
      </geometry>
      <material name="carbon_fiber">
        <color rgba="0.792156862745098 0.819607843137255 0.933333333333333 1"/>
      </material>
    </visual>
    <collision>
      <geometry>
        <mesh filename="package://jaco_description/meshes/jaco_link_finger_tip.stl" scale="0.0254 0.0254 0.0254"/>
      </geometry>
    </collision>
  </link>
  <joint name="jaco_joint_finger_tip_1" type="revolute">
    <parent link="jaco_link_finger_1"/>
    <child link="jaco_link_finger_tip_1"/>
    <axis xyz="0 0 1"/>
    <origin rpy="0 0 0" xyz="0.044094 -0.0029 0"/>
    <limit effort="30" lower="0" upper="0.698131700798" velocity="5"/>
  </joint>
  <link name="jaco_link_finger_tip_2">
    <visual>
      <geometry>
        <mesh filename="package://jaco_description/meshes/jaco_link_finger_tip.min.dae" scale="0.0254 0.0254 0.0254"/>
      </geometry>
      <material name="carbon_fiber">
        <color rgba="0.792156862745098 0.819607843137255 0.933333333333333 1"/>
      </material>
    </visual>
    <collision>
      <geometry>
        <mesh filename="package://jaco_description/meshes/jaco_link_finger_tip.stl" scale="0.0254 0.0254 0.0254"/>
      </geometry>
    </collision>
  </link>
  <joint name="jaco_joint_finger_tip_2" type="revolute">
    <parent link="jaco_link_finger_2"/>
    <child link="jaco_link_finger_tip_2"/>
    <axis xyz="0 0 1"/>
    <origin rpy="0 0 0" xyz="0.044094 -0.0029 0"/>
    <limit effort="30" lower="0" upper="0.698131700798" velocity="5"/>
  </joint>
  <link name="jaco_link_finger_tip_3">
    <visual>
      <geometry>
        <mesh filename="package://jaco_description/meshes/jaco_link_finger_tip.min.dae" scale="0.0254 0.0254 0.0254"/>
      </geometry>
      <material name="carbon_fiber">
        <color rgba="0.792156862745098 0.819607843137255 0.933333333333333 1"/>
      </material>
    </visual>
    <collision>
      <geometry>
        <mesh filename="package://jaco_description/meshes/jaco_link_finger_tip.stl" scale="0.0254 0.0254 0.0254"/>
      </geometry>
    </collision>
  </link>
  <joint name="jaco_joint_finger_tip_3" type="revolute">
    <parent link="jaco_link_finger_3"/>
    <child link="jaco_link_finger_tip_3"/>
    <axis xyz="0 0 1"/>
    <origin rpy="0 0 0" xyz="0.044094 -0.0029 0"/>
    <limit effort="30" lower="0" upper="0.698131700798" velocity="5"/>
  </joint>
</robot>

